Workbook

Sheet XXXX
A1: =#REF! -> #REF!
A2: SUMMARY BUDGET
A3: =#REF! -> #REF!
A4: =#REF! -> #REF!
A6: SECTION | B6: DESCRIPTION | C6: TOTAL
A7: INCOME | B7: UMCOR Sources | C7: =XXXXFinRep!D9 -> #REF!
A8: INCOME | B8: Other Grants | C8: =XXXXFinRep!D10 -> 0
A9: INCOME | B9: Annual Conference - UMC | C9: =XXXXFinRep!D11 -> 0
A10: INCOME | B10: Partner Annual Conference Contribution | C10: =XXXXFinRep!D12 -> 0
A11: INCOME | B11: Ministry of Health/Government | C11: =XXXXFinRep!D13 -> 0
A12: INCOME | B12: Local Churches and Individuals | C12: =XXXXFinRep!D14 -> 0
A13: INCOME | B13: Others-In-Kind Donation/Matching Funds | C13: =XXXXFinRep!D15 -> #REF!
B14: TOTAL INCOME | C14: =XXXXFinRep!D16 -> #REF!
A17: SECTION | B17: DESCRIPTION | C17: TOTAL
A19: SECTION A | B19: PROGRAM PERSONNEL | C19: =#REF! -> #REF!
A20: SECTION B | B20: DIRECT PROGRAM COSTS | C20: =#REF! -> #REF!
B21: =#REF! -> #REF! | C21: =#REF! -> #REF!
B22: =#REF! -> #REF! | C22: =#REF! -> #REF!
B23: =#REF! -> #REF! | C23: =#REF! -> #REF!
B24: =#REF! -> #REF! | C24: =#REF! -> #REF!
B25: =#REF! -> #REF! | C25: =#REF! -> #REF!
A27: SECTION C | B27: OTHER DIRECT PROGRAM COSTS | C27: =#REF! -> #REF!
B28: Visibility & Publication Costs | C28: =#REF! -> #REF!
B29: Monitoring & Evaluation Costs | C29: =#REF! -> #REF!
B30: TOTAL DIRECT PROGRAM COSTS | C30: =SUM(C27,C20,C19) -> #REF!
A32: SECTION D | B32: PROGRAM SUPPORT COSTS | C32: =#REF! -> #REF!
A33: SECTION D.1: | B33: SUPPORT PERSONNEL | C33: =#REF! -> #REF!
A34: SECTION D.2: | B34: EQUIPMENT | C34: =#REF! -> #REF!
A35: SECTION D.3: | B35: OFFICE RENTAL AND SUPPLIES | C35: =#REF! -> #REF!
A36: SECTION D.4: | B36: TRAVEL | C36: =#REF! -> #REF!
A37: SECTION D.5: | B37: COMMUNICATION | C37: =#REF! -> #REF!
A38: SECTION D.6: | B38: OTHER OPERATIONAL COSTS | C38: =#REF! -> #REF!
B39: TOTAL PROGRAM SUPPORT COSTS | C39: =SUM(C33:C38) -> #REF!
A41: SECTION E | B41: IN-KIND/MATCHING FUNDS | C41: =#REF! -> #REF!
A44: TOTAL PROJECT COST | C44: =SUM(C30,C39,C41) -> #REF!
A46: NET INCOME (TOTAL INCOME - TOTAL EXPENSE) | C46: =C14-C44 -> #REF!

Sheet XXXXX
A1: =#REF! -> #REF!
A2: SUMMARY REPORT
A3: =#REF! -> #REF!
A4: =#REF! -> #REF!
A6: SECTION | B6: CODE | C6: DESCRIPTION | D6: APPROVED INCOME | E6: TOTAL INCOME | F6: BALANCE
A7: INCOME | B7: UMCOR | C7: UMCOR Sources | D7: =SUMIF(XXXXFinRep!$B:$B,XXXXX!B7,XXXXFinRep!$D:$D) -> #REF! | E7: =SUMIF(XXXXFinRep!$B:$B,XXXXX!B7,XXXXFinRep!$H:$H) -> #REF! | F7: =SUMIF(XXXXFinRep!$B:$B,XXXXX!B7,XXXXFinRep!$I:$I) -> #REF!
A8: INCOME | B8: GRA | C8: Other Grants | D8: =SUMIF(XXXXFinRep!$B:$B,XXXXX!B8,XXXXFinRep!$D:$D) -> 0 | E8: =SUMIF(XXXXFinRep!$B:$B,XXXXX!B8,XXXXFinRep!$H:$H) -> 0 | F8: =SUMIF(XXXXFinRep!$B:$B,XXXXX!B8,XXXXFinRep!$I:$I) -> 0
A9: INCOME | B9: ANC | C9: Annual Conference - UMC | D9: =SUMIF(XXXXFinRep!$B:$B,XXXXX!B9,XXXXFinRep!$D:$D) -> 0 | E9: =SUMIF(XXXXFinRep!$B:$B,XXXXX!B9,XXXXFinRep!$H:$H) -> 0 | F9: =SUMIF(XXXXFinRep!$B:$B,XXXXX!B9,XXXXFinRep!$I:$I) -> 0
A10: INCOME | B10: PAC | C10: Partner Annual Conference Contribution | D10: =SUMIF(XXXXFinRep!$B:$B,XXXXX!B10,XXXXFinRep!$D:$D) -> 0 | E10: =SUMIF(XXXXFinRep!$B:$B,XXXXX!B10,XXXXFinRep!$H:$H) -> 0 | F10: =SUMIF(XXXXFinRep!$B:$B,XXXXX!B10,XXXXFinRep!$I:$I) -> 0
A11: INCOME | B11: MoH | C11: Ministry of Health/Government | D11: =SUMIF(XXXXFinRep!$B:$B,XXXXX!B11,XXXXFinRep!$D:$D) -> 0 | E11: =SUMIF(XXXXFinRep!$B:$B,XXXXX!B11,XXXXFinRep!$H:$H) -> 0 | F11: =SUMIF(XXXXFinRep!$B:$B,XXXXX!B11,XXXXFinRep!$I:$I) -> 0
A12: INCOME | B12: LC | C12: Local Churches and Individuals | D12: =SUMIF(XXXXFinRep!$B:$B,XXXXX!B12,XXXXFinRep!$D:$D) -> 0 | E12: =SUMIF(XXXXFinRep!$B:$B,XXXXX!B12,XXXXFinRep!$H:$H) -> 0 | F12: =SUMIF(XXXXFinRep!$B:$B,XXXXX!B12,XXXXFinRep!$I:$I) -> 0
A13: INCOME | B13: OTH | C13: Others-In-Kind Donation/Matching Funds | D13: =SUMIF(XXXXFinRep!$B:$B,XXXXX!B13,XXXXFinRep!$D:$D) -> #REF! | E13: =SUMIF(XXXXFinRep!$B:$B,XXXXX!B13,XXXXFinRep!$H:$H) -> 0 | F13: =SUMIF(XXXXFinRep!$B:$B,XXXXX!B13,XXXXFinRep!$I:$I) -> #REF!
C14: TOTAL INCOME | D14: =SUM(D7:D13) -> #REF! | E14: =SUM(E7:E13) -> #REF! | F14: =SUM(F7:F13) -> #REF!
A17: SECTION | C17: DESCRIPTION | D17: TOTAL | E17: TOTAL | F17: TOTAL
A19: SECTION A | B19: A.1 | C19: PROGRAM PERSONNEL | D19: =SUMIF(XXXXFinRep!$B:$B,XXXXX!B19,XXXXFinRep!$D:$D) -> #REF! | E19: =SUMIF(XXXXFinRep!$B:$B,XXXXX!B19,XXXXFinRep!$H:$H) -> #REF! | F19: =SUMIF(XXXXFinRep!$B:$B,XXXXX!B19,XXXXFinRep!$I:$I) -> #REF!
A20: SECTION B | C20: DIRECT PROGRAM COSTS
B21: B.1 | C21: =#REF! -> #REF! | D21: =SUMIF(XXXXFinRep!$B:$B,XXXXX!B21,XXXXFinRep!$D:$D) -> #REF! | E21: =SUMIF(XXXXFinRep!$B:$B,XXXXX!B21,XXXXFinRep!$H:$H) -> #REF! | F21: =SUMIF(XXXXFinRep!$B:$B,XXXXX!B21,XXXXFinRep!$I:$I) -> #REF!
B22: B.2 | C22: =#REF! -> #REF! | D22: =SUMIF(XXXXFinRep!$B:$B,XXXXX!B22,XXXXFinRep!$D:$D) -> #REF! | E22: =SUMIF(XXXXFinRep!$B:$B,XXXXX!B22,XXXXFinRep!$H:$H) -> #REF! | F22: =SUMIF(XXXXFinRep!$B:$B,XXXXX!B22,XXXXFinRep!$I:$I) -> #REF!
B23: B.3 | C23: =#REF! -> #REF! | D23: =SUMIF(XXXXFinRep!$B:$B,XXXXX!B23,XXXXFinRep!$D:$D) -> #REF! | E23: =SUMIF(XXXXFinRep!$B:$B,XXXXX!B23,XXXXFinRep!$H:$H) -> #REF! | F23: =SUMIF(XXXXFinRep!$B:$B,XXXXX!B23,XXXXFinRep!$I:$I) -> #REF!
B24: B.4 | C24: =#REF! -> #REF! | D24: =SUMIF(XXXXFinRep!$B:$B,XXXXX!B24,XXXXFinRep!$D:$D) -> #REF! | E24: =SUMIF(XXXXFinRep!$B:$B,XXXXX!B24,XXXXFinRep!$H:$H) -> #REF! | F24: =SUMIF(XXXXFinRep!$B:$B,XXXXX!B24,XXXXFinRep!$I:$I) -> #REF!
B25: B.5 | C25: =#REF! -> #REF! | D25: =SUMIF(XXXXFinRep!$B:$B,XXXXX!B25,XXXXFinRep!$D:$D) -> #REF! | E25: =SUMIF(XXXXFinRep!$B:$B,XXXXX!B25,XXXXFinRep!$H:$H) -> #REF! | F25: =SUMIF(XXXXFinRep!$B:$B,XXXXX!B25,XXXXFinRep!$I:$I) -> #REF!
A27: SECTION C | C27: OTHER DIRECT PROGRAM COSTS
B28: C.1 | C28: Visibility & Publication Costs | D28: =SUMIF(XXXXFinRep!$B:$B,XXXXX!B28,XXXXFinRep!$D:$D) -> #REF! | E28: =SUMIF(XXXXFinRep!$B:$B,XXXXX!B28,XXXXFinRep!$H:$H) -> #REF! | F28: =SUMIF(XXXXFinRep!$B:$B,XXXXX!B28,XXXXFinRep!$I:$I) -> #REF!
B29: C.2 | C29: Monitoring & Evaluation Costs | D29: =SUMIF(XXXXFinRep!$B:$B,XXXXX!B29,XXXXFinRep!$D:$D) -> #REF! | E29: =SUMIF(XXXXFinRep!$B:$B,XXXXX!B29,XXXXFinRep!$H:$H) -> #REF! | F29: =SUMIF(XXXXFinRep!$B:$B,XXXXX!B29,XXXXFinRep!$I:$I) -> #REF!
C30: TOTAL DIRECT PROGRAM COSTS | D30: =SUM(D19:D29) -> #REF! | E30: =SUM(E19:E29) -> #REF! | F30: =SUM(F19:F29) -> #REF!
A32: SECTION D | C32: PROGRAM SUPPORT COSTS
B33: D.1 | C33: SUPPORT PERSONNEL | D33: =SUMIF(XXXXFinRep!$B:$B,XXXXX!B33,XXXXFinRep!$D:$D) -> #REF! | E33: =SUMIF(XXXXFinRep!$B:$B,XXXXX!B33,XXXXFinRep!$H:$H) -> #REF! | F33: =SUMIF(XXXXFinRep!$B:$B,XXXXX!B33,XXXXFinRep!$I:$I) -> #REF!
B34: D.2 | C34: EQUIPMENT | D34: =SUMIF(XXXXFinRep!$B:$B,XXXXX!B34,XXXXFinRep!$D:$D) -> #REF! | E34: =SUMIF(XXXXFinRep!$B:$B,XXXXX!B34,XXXXFinRep!$H:$H) -> #REF! | F34: =SUMIF(XXXXFinRep!$B:$B,XXXXX!B34,XXXXFinRep!$I:$I) -> #REF!
B35: D.3 | C35: OFFICE RENTAL AND SUPPLIES | D35: =SUMIF(XXXXFinRep!$B:$B,XXXXX!B35,XXXXFinRep!$D:$D) -> #REF! | E35: =SUMIF(XXXXFinRep!$B:$B,XXXXX!B35,XXXXFinRep!$H:$H) -> #REF! | F35: =SUMIF(XXXXFinRep!$B:$B,XXXXX!B35,XXXXFinRep!$I:$I) -> #REF!
B36: D.4 | C36: TRAVEL | D36: =SUMIF(XXXXFinRep!$B:$B,XXXXX!B36,XXXXFinRep!$D:$D) -> #REF! | E36: =SUMIF(XXXXFinRep!$B:$B,XXXXX!B36,XXXXFinRep!$H:$H) -> #REF! | F36: =SUMIF(XXXXFinRep!$B:$B,XXXXX!B36,XXXXFinRep!$I:$I) -> #REF!
B37: D.5 | C37: COMMUNICATION | D37: =SUMIF(XXXXFinRep!$B:$B,XXXXX!B37,XXXXFinRep!$D:$D) -> #REF! | E37: =SUMIF(XXXXFinRep!$B:$B,XXXXX!B37,XXXXFinRep!$H:$H) -> #REF! | F37: =SUMIF(XXXXFinRep!$B:$B,XXXXX!B37,XXXXFinRep!$I:$I) -> #REF!
B38: D.6 | C38: OTHER OPERATIONAL COSTS | D38: =SUMIF(XXXXFinRep!$B:$B,XXXXX!B38,XXXXFinRep!$D:$D) -> #REF! | E38: =SUMIF(XXXXFinRep!$B:$B,XXXXX!B38,XXXXFinRep!$H:$H) -> #REF! | F38: =SUMIF(XXXXFinRep!$B:$B,XXXXX!B38,XXXXFinRep!$I:$I) -> #REF!
C39: TOTAL PROGRAM SUPPORT COSTS | D39: =SUM(D33:D38) -> #REF! | E39: =SUM(E33:E38) -> #REF! | F39: =SUM(F33:F38) -> #REF!
C41: TOTAL UMCOR GRANT BUDGET | D41: =D39+D30 -> #REF! | E41: =E39+E30 -> #REF! | F41: =F39+F30 -> #REF!
A43: SECTION E | B43: E.1 | C43: IN-KIND/MATCHING FUNDS | D43: =SUMIF(XXXXFinRep!$B:$B,XXXXX!B43,XXXXFinRep!$D:$D) -> #REF! | E43: =SUMIF(XXXXFinRep!$B:$B,XXXXX!B43,XXXXFinRep!$H:$H) -> 0 | F43: =SUMIF(XXXXFinRep!$B:$B,XXXXX!B43,XXXXFinRep!$I:$I) -> #REF!
A46: TOTAL PROGRAM COST | D46: =SUM(D41,D43) -> #REF! | E46: =SUM(E41,E43) -> #REF! | F46: =SUM(F41,F43) -> #REF!
A48: NET INCOME (TOTAL INCOME - TOTAL EXPENSE) | D48: =D14-D46 -> #REF! | E48: =E14-E46 -> #REF! | F48: =F14-F46 -> #REF!

Sheet XXXXFinRep
B2: =#REF! -> #REF!
B3: FINANCIAL REPORT
B4: =#REF! -> #REF!
B5: =#REF! -> #REF!
C7: =#REF! -> #REF! | D7: =#REF! -> #REF!
B8: CODE | C8: DESCRIPTION | D8: APPROVED INCOME | E8: FUNDS RECEIVED PERIOD 1 | F8: FUNDS RECEIVED PERIOD 2 | G8: FUNDS RECEIVED PERIOD 3 | H8: TOTAL USD | I8: BALANCE USD
B9: UMCOR | C9: UMCOR Sources | D9: =D276 -> #REF! | E9: =SUMIF(#REF!,XXXXFinRep!B9,#REF!) -> #REF! | F9: =SUMIF(#REF!,XXXXFinRep!B9,#REF!) -> #REF! | G9: =SUMIF(#REF!,XXXXFinRep!B9,#REF!) -> #REF! | H9: =SUM(E9:G9) -> #REF! | I9: =D9-H9 -> #REF!
B10: GRA | C10: Other Grants | H10: =SUM(E10:G10) -> 0 | I10: =D10-H10 -> 0
B11: ANC | C11: Annual Conference - UMC | H11: =SUM(E11:G11) -> 0 | I11: =D11-H11 -> 0
B12: PAC | C12: Partner Annual Conference Contribution | H12: =SUM(E12:G12) -> 0 | I12: =D12-H12 -> 0
B13: MoH | C13: Ministry of Health/Government | H13: =SUM(E13:G13) -> 0 | I13: =D13-H13 -> 0
B14: LC | C14: Local Churches and Individuals | H14: =SUM(E14:G14) -> 0 | I14: =D14-H14 -> 0
B15: OTH | C15: Others-In-Kind Donation/Matching Funds | D15: =D289 -> #REF! | H15: =SUM(E15:G15) -> 0 | I15: =D15-H15 -> #REF!
C16: TOTAL INCOME | D16: =SUM(D9:D15) -> #REF! | E16: =SUM(E9:E15) -> #REF! | F16: =SUM(F9:F15) -> #REF! | G16: =SUM(G9:G15) -> #REF! | H16: =SUM(H9:H15) -> #REF! | I16: =SUM(I9:I15) -> #REF!
B18: CODE | C18: BUDGET DESCRIPTION | D18: APPROVED BUDGET USD | E18: EXPENSES PERIOD 1 USD | F18: EXPENSES PERIOD 2 USD | G18: EXPENSES PERIOD 3 USD | H18: TOTAL EXPENSES USD | I18: BALANCE USD
B19: SECTION A: PROGRAM PERSONNEL
C20: Position
A21: 1 | B21: =VLOOKUP(A21,#REF!,2,FALSE) -> #REF! | C21: =VLOOKUP(B21,#REF!,2,FALSE) -> #REF! | D21: =SUMIF(#REF!,XXXXFinRep!B21,#REF!) -> #REF! | E21: =SUMIF(#REF!,XXXXFinRep!B21,#REF!)+SUMIF(#REF!,XXXXFinRep!B21,#REF!) -> #REF! | F21: =SUMIF(#REF!,XXXXFinRep!B21,#REF!)+SUMIF(#REF!,XXXXFinRep!B21,#REF!) -> #REF! | G21: =SUMIF(#REF!,XXXXFinRep!B21,#REF!)+SUMIF(#REF!,XXXXFinRep!B21,#REF!) -> #REF! | H21: =SUM(E21,F21,G21) -> #REF! | I21: =SUM(D21-H21) -> #REF!
A22: 2 | B22: =VLOOKUP(A22,#REF!,2,FALSE) -> #REF! | C22: =VLOOKUP(B22,#REF!,2,FALSE) -> #REF! | D22: =SUMIF(#REF!,XXXXFinRep!B22,#REF!) -> #REF! | E22: =SUMIF(#REF!,XXXXFinRep!B22,#REF!)+SUMIF(#REF!,XXXXFinRep!B22,#REF!) -> #REF! | F22: =SUMIF(#REF!,XXXXFinRep!B22,#REF!)+SUMIF(#REF!,XXXXFinRep!B22,#REF!) -> #REF! | G22: =SUMIF(#REF!,XXXXFinRep!B22,#REF!)+SUMIF(#REF!,XXXXFinRep!B22,#REF!) -> #REF! | H22: =SUM(E22,F22,G22) -> #REF! | I22: =SUM(D22-H22) -> #REF!
A23: 3 | B23: =VLOOKUP(A23,#REF!,2,FALSE) -> #REF! | C23: =VLOOKUP(B23,#REF!,2,FALSE) -> #REF! | D23: =SUMIF(#REF!,XXXXFinRep!B23,#REF!) -> #REF! | E23: =SUMIF(#REF!,XXXXFinRep!B23,#REF!)+SUMIF(#REF!,XXXXFinRep!B23,#REF!) -> #REF! | F23: =SUMIF(#REF!,XXXXFinRep!B23,#REF!)+SUMIF(#REF!,XXXXFinRep!B23,#REF!) -> #REF! | G23: =SUMIF(#REF!,XXXXFinRep!B23,#REF!)+SUMIF(#REF!,XXXXFinRep!B23,#REF!) -> #REF! | H23: =SUM(E23,F23,G23) -> #REF! | I23: =SUM(D23-H23) -> #REF!
A24: 4 | B24: =VLOOKUP(A24,#REF!,2,FALSE) -> #REF! | C24: =VLOOKUP(B24,#REF!,2,FALSE) -> #REF! | D24: =SUMIF(#REF!,XXXXFinRep!B24,#REF!) -> #REF! | E24: =SUMIF(#REF!,XXXXFinRep!B24,#REF!)+SUMIF(#REF!,XXXXFinRep!B24,#REF!) -> #REF! | F24: =SUMIF(#REF!,XXXXFinRep!B24,#REF!)+SUMIF(#REF!,XXXXFinRep!B24,#REF!) -> #REF! | G24: =SUMIF(#REF!,XXXXFinRep!B24,#REF!)+SUMIF(#REF!,XXXXFinRep!B24,#REF!) -> #REF! | H24: =SUM(E24,F24,G24) -> #REF! | I24: =SUM(D24-H24) -> #REF!
A25: 5 | B25: =VLOOKUP(A25,#REF!,2,FALSE) -> #REF! | C25: =VLOOKUP(B25,#REF!,2,FALSE) -> #REF! | D25: =SUMIF(#REF!,XXXXFinRep!B25,#REF!) -> #REF! | E25: =SUMIF(#REF!,XXXXFinRep!B25,#REF!)+SUMIF(#REF!,XXXXFinRep!B25,#REF!) -> #REF! | F25: =SUMIF(#REF!,XXXXFinRep!B25,#REF!)+SUMIF(#REF!,XXXXFinRep!B25,#REF!) -> #REF! | G25: =SUMIF(#REF!,XXXXFinRep!B25,#REF!)+SUMIF(#REF!,XXXXFinRep!B25,#REF!) -> #REF! | H25: =SUM(E25,F25,G25) -> #REF! | I25: =SUM(D25-H25) -> #REF!
A26: 6 | B26: =VLOOKUP(A26,#REF!,2,FALSE) -> #REF! | C26: =VLOOKUP(B26,#REF!,2,FALSE) -> #REF! | D26: =SUMIF(#REF!,XXXXFinRep!B26,#REF!) -> #REF! | E26: =SUMIF(#REF!,XXXXFinRep!B26,#REF!)+SUMIF(#REF!,XXXXFinRep!B26,#REF!) -> #REF! | F26: =SUMIF(#REF!,XXXXFinRep!B26,#REF!)+SUMIF(#REF!,XXXXFinRep!B26,#REF!) -> #REF! | G26: =SUMIF(#REF!,XXXXFinRep!B26,#REF!)+SUMIF(#REF!,XXXXFinRep!B26,#REF!) -> #REF! | H26: =SUM(E26,F26,G26) -> #REF! | I26: =SUM(D26-H26) -> #REF!
A27: 7 | B27: =VLOOKUP(A27,#REF!,2,FALSE) -> #REF! | C27: =VLOOKUP(B27,#REF!,2,FALSE) -> #REF! | D27: =SUMIF(#REF!,XXXXFinRep!B27,#REF!) -> #REF! | E27: =SUMIF(#REF!,XXXXFinRep!B27,#REF!)+SUMIF(#REF!,XXXXFinRep!B27,#REF!) -> #REF! | F27: =SUMIF(#REF!,XXXXFinRep!B27,#REF!)+SUMIF(#REF!,XXXXFinRep!B27,#REF!) -> #REF! | G27: =SUMIF(#REF!,XXXXFinRep!B27,#REF!)+SUMIF(#REF!,XXXXFinRep!B27,#REF!) -> #REF! | H27: =SUM(E27,F27,G27) -> #REF! | I27: =SUM(D27-H27) -> #REF!
A28: 8 | B28: =VLOOKUP(A28,#REF!,2,FALSE) -> #REF! | C28: =VLOOKUP(B28,#REF!,2,FALSE) -> #REF! | D28: =SUMIF(#REF!,XXXXFinRep!B28,#REF!) -> #REF! | E28: =SUMIF(#REF!,XXXXFinRep!B28,#REF!)+SUMIF(#REF!,XXXXFinRep!B28,#REF!) -> #REF! | F28: =SUMIF(#REF!,XXXXFinRep!B28,#REF!)+SUMIF(#REF!,XXXXFinRep!B28,#REF!) -> #REF! | G28: =SUMIF(#REF!,XXXXFinRep!B28,#REF!)+SUMIF(#REF!,XXXXFinRep!B28,#REF!) -> #REF! | H28: =SUM(E28,F28,G28) -> #REF! | I28: =SUM(D28-H28) -> #REF!
A29: 9 | B29: =VLOOKUP(A29,#REF!,2,FALSE) -> #REF! | C29: =VLOOKUP(B29,#REF!,2,FALSE) -> #REF! | D29: =SUMIF(#REF!,XXXXFinRep!B29,#REF!) -> #REF! | E29: =SUMIF(#REF!,XXXXFinRep!B29,#REF!)+SUMIF(#REF!,XXXXFinRep!B29,#REF!) -> #REF! | F29: =SUMIF(#REF!,XXXXFinRep!B29,#REF!)+SUMIF(#REF!,XXXXFinRep!B29,#REF!) -> #REF! | G29: =SUMIF(#REF!,XXXXFinRep!B29,#REF!)+SUMIF(#REF!,XXXXFinRep!B29,#REF!) -> #REF! | H29: =SUM(E29,F29,G29) -> #REF! | I29: =SUM(D29-H29) -> #REF!
A30: 10 | B30: =VLOOKUP(A30,#REF!,2,FALSE) -> #REF! | C30: =VLOOKUP(B30,#REF!,2,FALSE) -> #REF! | D30: =SUMIF(#REF!,XXXXFinRep!B30,#REF!) -> #REF! | E30: =SUMIF(#REF!,XXXXFinRep!B30,#REF!)+SUMIF(#REF!,XXXXFinRep!B30,#REF!) -> #REF! | F30: =SUMIF(#REF!,XXXXFinRep!B30,#REF!)+SUMIF(#REF!,XXXXFinRep!B30,#REF!) -> #REF! | G30: =SUMIF(#REF!,XXXXFinRep!B30,#REF!)+SUMIF(#REF!,XXXXFinRep!B30,#REF!) -> #REF! | H30: =SUM(E30,F30,G30) -> #REF! | I30: =SUM(D30-H30) -> #REF!
B31: A.1 | C31: TOTAL PROGRAM PERSONNEL | D31: =SUM(D21:D30) -> #REF! | E31: =SUM(E21:E30) -> #REF! | F31: =SUM(F21:F30) -> #REF! | G31: =SUM(G21:G30) -> #REF! | H31: =SUM(H21:H30) -> #REF! | I31: =SUM(I21:I30) -> #REF!
B33: SECTION B: DIRECT PROGRAM COSTS
B34: 1 | C34: =VLOOKUP(B34,#REF!,2,FALSE) -> #REF!
A35: 11 | B35: =VLOOKUP(A35,#REF!,2,FALSE) -> #REF! | C35: =VLOOKUP(B35,#REF!,2,FALSE) -> #REF! | D35: =SUMIF(#REF!,XXXXFinRep!B35,#REF!) -> #REF! | E35: =SUMIF(#REF!,XXXXFinRep!B35,#REF!)+SUMIF(#REF!,XXXXFinRep!B35,#REF!) -> #REF! | F35: =SUMIF(#REF!,XXXXFinRep!B35,#REF!)+SUMIF(#REF!,XXXXFinRep!B35,#REF!) -> #REF! | G35: =SUMIF(#REF!,XXXXFinRep!B35,#REF!)+SUMIF(#REF!,XXXXFinRep!B35,#REF!) -> #REF! | H35: =SUM(E35,F35,G35) -> #REF! | I35: =SUM(D35-H35) -> #REF!
A36: 12 | B36: =VLOOKUP(A36,#REF!,2,FALSE) -> #REF! | C36: =VLOOKUP(B36,#REF!,2,FALSE) -> #REF! | D36: =SUMIF(#REF!,XXXXFinRep!B36,#REF!) -> #REF! | E36: =SUMIF(#REF!,XXXXFinRep!B36,#REF!)+SUMIF(#REF!,XXXXFinRep!B36,#REF!) -> #REF! | F36: =SUMIF(#REF!,XXXXFinRep!B36,#REF!)+SUMIF(#REF!,XXXXFinRep!B36,#REF!) -> #REF! | G36: =SUMIF(#REF!,XXXXFinRep!B36,#REF!)+SUMIF(#REF!,XXXXFinRep!B36,#REF!) -> #REF! | H36: =SUM(E36,F36,G36) -> #REF! | I36: =SUM(D36-H36) -> #REF!
A37: 13 | B37: =VLOOKUP(A37,#REF!,2,FALSE) -> #REF! | C37: =VLOOKUP(B37,#REF!,2,FALSE) -> #REF! | D37: =SUMIF(#REF!,XXXXFinRep!B37,#REF!) -> #REF! | E37: =SUMIF(#REF!,XXXXFinRep!B37,#REF!)+SUMIF(#REF!,XXXXFinRep!B37,#REF!) -> #REF! | F37: =SUMIF(#REF!,XXXXFinRep!B37,#REF!)+SUMIF(#REF!,XXXXFinRep!B37,#REF!) -> #REF! | G37: =SUMIF(#REF!,XXXXFinRep!B37,#REF!)+SUMIF(#REF!,XXXXFinRep!B37,#REF!) -> #REF! | H37: =SUM(E37,F37,G37) -> #REF! | I37: =SUM(D37-H37) -> #REF!
A38: 14 | B38: =VLOOKUP(A38,#REF!,2,FALSE) -> #REF! | C38: =VLOOKUP(B38,#REF!,2,FALSE) -> #REF! | D38: =SUMIF(#REF!,XXXXFinRep!B38,#REF!) -> #REF! | E38: =SUMIF(#REF!,XXXXFinRep!B38,#REF!)+SUMIF(#REF!,XXXXFinRep!B38,#REF!) -> #REF! | F38: =SUMIF(#REF!,XXXXFinRep!B38,#REF!)+SUMIF(#REF!,XXXXFinRep!B38,#REF!) -> #REF! | G38: =SUMIF(#REF!,XXXXFinRep!B38,#REF!)+SUMIF(#REF!,XXXXFinRep!B38,#REF!) -> #REF! | H38: =SUM(E38,F38,G38) -> #REF! | I38: =SUM(D38-H38) -> #REF!
A39: 15 | B39: =VLOOKUP(A39,#REF!,2,FALSE) -> #REF! | C39: =VLOOKUP(B39,#REF!,2,FALSE) -> #REF! | D39: =SUMIF(#REF!,XXXXFinRep!B39,#REF!) -> #REF! | E39: =SUMIF(#REF!,XXXXFinRep!B39,#REF!)+SUMIF(#REF!,XXXXFinRep!B39,#REF!) -> #REF! | F39: =SUMIF(#REF!,XXXXFinRep!B39,#REF!)+SUMIF(#REF!,XXXXFinRep!B39,#REF!) -> #REF! | G39: =SUMIF(#REF!,XXXXFinRep!B39,#REF!)+SUMIF(#REF!,XXXXFinRep!B39,#REF!) -> #REF! | H39: =SUM(E39,F39,G39) -> #REF! | I39: =SUM(D39-H39) -> #REF!
A40: 16 | B40: =VLOOKUP(A40,#REF!,2,FALSE) -> #REF! | C40: =VLOOKUP(B40,#REF!,2,FALSE) -> #REF! | D40: =SUMIF(#REF!,XXXXFinRep!B40,#REF!) -> #REF! | E40: =SUMIF(#REF!,XXXXFinRep!B40,#REF!)+SUMIF(#REF!,XXXXFinRep!B40,#REF!) -> #REF! | F40: =SUMIF(#REF!,XXXXFinRep!B40,#REF!)+SUMIF(#REF!,XXXXFinRep!B40,#REF!) -> #REF! | G40: =SUMIF(#REF!,XXXXFinRep!B40,#REF!)+SUMIF(#REF!,XXXXFinRep!B40,#REF!) -> #REF! | H40: =SUM(E40,F40,G40) -> #REF! | I40: =SUM(D40-H40) -> #REF!
A41: 17 | B41: =VLOOKUP(A41,#REF!,2,FALSE) -> #REF! | C41: =VLOOKUP(B41,#REF!,2,FALSE) -> #REF! | D41: =SUMIF(#REF!,XXXXFinRep!B41,#REF!) -> #REF! | E41: =SUMIF(#REF!,XXXXFinRep!B41,#REF!)+SUMIF(#REF!,XXXXFinRep!B41,#REF!) -> #REF! | F41: =SUMIF(#REF!,XXXXFinRep!B41,#REF!)+SUMIF(#REF!,XXXXFinRep!B41,#REF!) -> #REF! | G41: =SUMIF(#REF!,XXXXFinRep!B41,#REF!)+SUMIF(#REF!,XXXXFinRep!B41,#REF!) -> #REF! | H41: =SUM(E41,F41,G41) -> #REF! | I41: =SUM(D41-H41) -> #REF!
A42: 18 | B42: =VLOOKUP(A42,#REF!,2,FALSE) -> #REF! | C42: =VLOOKUP(B42,#REF!,2,FALSE) -> #REF! | D42: =SUMIF(#REF!,XXXXFinRep!B42,#REF!) -> #REF! | E42: =SUMIF(#REF!,XXXXFinRep!B42,#REF!)+SUMIF(#REF!,XXXXFinRep!B42,#REF!) -> #REF! | F42: =SUMIF(#REF!,XXXXFinRep!B42,#REF!)+SUMIF(#REF!,XXXXFinRep!B42,#REF!) -> #REF! | G42: =SUMIF(#REF!,XXXXFinRep!B42,#REF!)+SUMIF(#REF!,XXXXFinRep!B42,#REF!) -> #REF! | H42: =SUM(E42,F42,G42) -> #REF! | I42: =SUM(D42-H42) -> #REF!
A43: 19 | B43: =VLOOKUP(A43,#REF!,2,FALSE) -> #REF! | C43: =VLOOKUP(B43,#REF!,2,FALSE) -> #REF! | D43: =SUMIF(#REF!,XXXXFinRep!B43,#REF!) -> #REF! | E43: =SUMIF(#REF!,XXXXFinRep!B43,#REF!)+SUMIF(#REF!,XXXXFinRep!B43,#REF!) -> #REF! | F43: =SUMIF(#REF!,XXXXFinRep!B43,#REF!)+SUMIF(#REF!,XXXXFinRep!B43,#REF!) -> #REF! | G43: =SUMIF(#REF!,XXXXFinRep!B43,#REF!)+SUMIF(#REF!,XXXXFinRep!B43,#REF!) -> #REF! | H43: =SUM(E43,F43,G43) -> #REF! | I43: =SUM(D43-H43) -> #REF!
A44: 20 | B44: =VLOOKUP(A44,#REF!,2,FALSE) -> #REF! | C44: =VLOOKUP(B44,#REF!,2,FALSE) -> #REF! | D44: =SUMIF(#REF!,XXXXFinRep!B44,#REF!) -> #REF! | E44: =SUMIF(#REF!,XXXXFinRep!B44,#REF!)+SUMIF(#REF!,XXXXFinRep!B44,#REF!) -> #REF! | F44: =SUMIF(#REF!,XXXXFinRep!B44,#REF!)+SUMIF(#REF!,XXXXFinRep!B44,#REF!) -> #REF! | G44: =SUMIF(#REF!,XXXXFinRep!B44,#REF!)+SUMIF(#REF!,XXXXFinRep!B44,#REF!) -> #REF! | H44: =SUM(E44,F44,G44) -> #REF! | I44: =SUM(D44-H44) -> #REF!
...

Sheet REQ ZG UMCOR 4 _RU
B2: Church World Service
B3: DETAIL BUDGET
B4: Project Title: CWS 2025 Ukraine Response Program – Serbia and Moldova
B5: Project Period: 1 Jan 2025 to 31 Dec 2025 | H5: Rev. 3/23
C7: Дата начала: 1 Февраль 2026 | D7: Дата окончания: 1 Август 2026
B8: CODE | C8: DESCRIPTION | H8: APPROVED INCOME
B9: UMCOR | C9: UMCOR Sources
B10: GRA | C10: Other Grants | H10: 0
B11: ANC | C11: Annual Conference - UMC | H11: 0
B12: PAC | C12: Partner Annual Conference Contribution | H12: 0
B13: MoH | C13: Ministry of Health/Government | H13: 0
B14: LC | C14: Local Churches and Individuals | H14: 0
B15: OTH | C15: Others-In-Kind Donation/Matching Funds | H15: =H132 -> 0
C16: TOTAL INCOME | H16: =H134 -> 58999
B19: CODE | C19: BUDGET DESCRIPTION | D19: UNIT MEASURE | E19: QUANTITY | F19: UNIT COST | G19: FREQUENCY/#MONTH/ DAY | H19: TOTAL | I19: BUDGET NOTES
B20: SECTION A: PROGRAM PERSONNEL
C21: Position
H22: 0
B24: SECTION B: DIRECT PROGRAM COSTS
B25: 1 | C25: Objective 1: To meet basic needs of refugees and migrants affected
C26: Sub-Total: Objective 1 | H26: 0
B27: 1 | C27: Objective 2: Cash Assistance
A28: 21 | B28: PRG11 | C28: Закупка/Выдача Ваучеров / Vouchers | D28: Lump sum | E28: 1 | F28: 5000 | G28: 1 | H28: =E28*F28*G28 -> 5000 | I28: Закупка ваучеров METRO (300 MDL/Ваучер), планируется выдать 281 ваучер в течении 6 месяцев проектной деятельности
A29: 22 | B29: PRG21 | C29: Супервайзер - Молдова | D29: Person/FTE | E29: 1.9 | F29: 610 | G29: 6 | H29: =E29*F29*G29 -> 6954 | I29: 2 позиция. Контролирует MHPSS (1.0 FTE) Будулай; Курирует ведение дел (0.9 FTE) Валя
A30: 23 | B30: PRG22 | C30: Зарплата юриста центра ZG -Молдова | D30: Person/FTE | E30: 0.125 | F30: 1000 | G30: 6 | H30: =E30*F30*G30 -> 750 | I30: 0.125 FTE, 1 позиция. Обеспечивает соблюдение всех применимых законов и нормативных актов.
A31: 24 | B31: PRG23 | C31: Расходы на коммунальные услуги ZG -Молдова | D31: Month | E31: 1 | F31: 600 | G31: 6 | H31: =E31*F31*G31 -> 3600 | I31: Свет, вода, тепло, интернет
A32: 25 | B32: PRG24 | C32: ZG аренда -Молдова | D32: Month | E32: 1 | F32: 550 | G32: 6 | H32: =E32*F32*G32 -> 3300 | I32: Ежемесячная стоимость аренды помещения в центре программы
A33: 26 | B33: PRG25 | C33: ZG Чистящие средства -Молдова | D33: Month | E33: 0.5 | F33: 50 | G33: 6 | H33: =E33*F33*G33 -> 150 | I33: Чистящие средства для ZG
A34: 27 | B34: PRG26 | C34: ZG питьевая вода -Молдова | D34: Month | E34: 0.5 | F34: 70 | G34: 6 | H34: =E34*F34*G34 -> 210 | I34: Для сотрудников и клиентов
A35: 28 | B35: PRG27 | C35: Канцелярские и кухонные принадлежности ZG -Молдова | D35: Month | E35: 0.5 | F35: 50 | G35: 6 | H35: =E35*F35*G35 -> 150 | I35: Печать обязательных государственных чеков для каждого получателя, кофейных чашек и т. д.
A36: 29 | B36: PRG29 | C36: Гибкое финансирование кейс менеджмент-Молдова | D36: Month | E36: 1 | F36: 670 | G36: 6 | H36: =E36*F36*G36 -> 4020 | I36: Покрытие потребностей, определенных в СМ - профессиональное обучение, жилье, питание, лекарства и т.д.
A37: 30 | B37: PRG30 | C37: Хозяйственные работники центра | D37: Person/FTE | E37: 2 | F37: 300 | G37: 6 | H37: =E37*F37*G37 -> 3600 | I37: 1.0 FTE, 2 позиции (Андрей). Обеспечивает материально-техническую поддержку: доставка необходимых товаров (вода, кофе, печенье), мелкие ремонты, транспортировка, обслуживание центра, поддержание порядка и устранение технических неисправностей; (Виорика) Уборка помещений центра, проведение мастер классов для детей.
A38: 31 | B38: PRG21 | C38: Медиа-координатор по информационному сопровождению и работе с молодёжью (Илья) | D38: Person/FTE | E38: 1 | F38: 550 | G38: 6 | H38: =E38*F38*G38 -> 3300 | I38: 1,0 FTE, 1 позициия (Илья). Отвечает за создание и публикацию контента в Instagram и Facebook, готовит анонсы мероприятий, помогает в подготовке опросников, взаимодействует с молодёжью и участвует в организации мероприятий.
A39: 32 | B39: PRG26 | C39: Экстренный бюджет | D39: Month | E39: 1 | F39: 50 | G39: 6 | H39: =E39*F39*G39 -> 300 | I39: Закупка оборудования при поломке, замена оборудования, комплектующих, расходники центра
C40: Sub-Total: Objective 2 | H40: =SUM(H28:H39) -> 31334
C42: Objective 3: To provide shelter assistance for vulnerable refugees and migrants in need of short-term accommodation.
C43: Sub-Total: Objective 3 | H43: 0
B45: 3 | C45: Objective 4: Psychosocial, Counseling & Medical
A46: 40 | B46: PRG40 | C46: Врач ZG | D46: Person/FTE | E46: 0.25 | F46: 1200 | G46: 6 | H46: =E46*F46*G46 -> 1800 | I46: 0,25 FTE, 1 позиция. Оказывает медицинские услуги участникам программы. Михайл
A47: 41 | B47: PRG41 | C47: Психологи | D47: Person/FTE | E47: 1.5 | F47: 540 | G47: 6 | H47: =E47*F47*G47 -> 4860 | I47: 0,75 FTE, 2 позиции. Проводит индивидуальные и групповые психологические сессии для участников программы. | N47: =(H57/8)*6 -> 6783.75
...
